Workbook

Sheet LEIA-ME
A1: COPA REVOADA — planilha de dados
A3: O que mudou | B3: Puxei automaticamente as escalações que estavam espalhadas pela aba Dados da planilha antiga.
B4: 8 dos 13 jogos fecharam com o placar. O resto está listado na aba PENDENCIAS.
A6: Amarelo | B6: você preenche
A7: Cinza | B7: veio da planilha antiga — confira
A8: Laranja | B8: tem pendência, veja a aba PENDENCIAS
A10: JOGADORES | B10: uma linha por pessoa, para sempre. O id é a chave de todas as outras abas.
A11: TIMES | B11: um time por temporada, com as cores que viram o escudo no site.
A12: JOGOS | B12: uma linha por partida. Marque o time vencedor em campeao_time_id.
A13: ESCALACOES | B13: uma linha por jogador por jogo. Já veio preenchida onde deu.
A14: TROFEUS | B14: uma linha por troféu entregue, inclusive a piroquinha.
A15: CLIPES | B15: melhores momentos. Não precisa cortar vídeo: cole o ID do YouTube e o segundo.
A16: PENDENCIAS | B16: a lista do que falta resolver, em ordem de importância.
A17: CONFERE | B17: fórmula que compara os gols lançados com o placar de cada jogo.
A19: Fotos | B19: pasta fotos/ do repositório, arquivo com o nome do id (fanta.jpg). Quadrada, 600x600.

Sheet CONFIG
A1: Chave mestra: é ela que autoriza o app a criar a aba de um jogo novo. Cada aba de jogo tem a sua própria chave na célula B2 dela.
A2: chave_mestra | B2: TROQUE-ESTA-CHAVE | C2: <- digite a sua aqui; nunca comitar no repositório

Sheet JOGADORES
A1: Amarelo = preencher. A última coluna é só referência, pode apagar depois de conferir.
A3: id | B3: apelido | C3: nome_completo | D3: posicao | E3: numero_camisa | F3: no_ranking | G3: como_aparece_na_planilha_antiga
A4: andre | B4: Andre | F4: SIM | G4: Andre / André / andré
A5: arthur | B5: Arthur | D5: GOL | F5: SIM | G5: Arthur / Arthur gk
A6: bala | B6: Bala | F6: SIM | G6: Bala
A7: berna | B7: Berna | G7: Berna / Mito
A8: borba | B8: Borba | F8: SIM | G8: Borba / borba
A9: bruno | B9: Bruno | F9: SIM | G9: Bruno / bruno
A10: correa | B10: Be Correa | D10: GOL | F10: SIM | G10: Correa / bernardoc
A11: danilim | B11: Danilim | F11: SIM | G11: Danilim / danilim
A12: davi | B12: Davi | F12: SIM | G12: davi
A13: dereck | B13: Dereck | G13: Dereck
A14: derek | B14: Derek | G14: Derek / derek
A15: dereka | B15: Dereka | G15: Dereka
A16: enzo | B16: Enzo | F16: SIM | G16: Enzo / enzo
A17: fanta | B17: Fanta | F17: SIM | G17: Fanta / fanta
A18: garopaba | B18: Garopaba | F18: SIM | G18: Garopa / Garopaba / garopa / garopaba
A19: glauber | B19: Glauber | F19: SIM | G19: Glauber / glauber
A20: hanon | B20: Hanon | F20: SIM | G20: Hanon / hanon
A21: henrique | B21: Henrique | F21: SIM | G21: Henrique
A22: joao | B22: Joao | F22: SIM | G22: Joao
A23: kretzer | B23: Kretzer | F23: SIM | G23: Kretzer / kretzer / vitim
A24: leo | B24: Leo | F24: SIM | G24: Leo / leo
A25: leobittencourt | B25: Leobittencourt | F25: SIM
A26: leogodinho | B26: Leo Godinho | F26: SIM | G26: Leo Godinho
A27: letti | B27: Letti | F27: SIM | G27: Letti / letti
A28: luigi | B28: Luigi | F28: SIM | G28: Luigi
A29: marucco | B29: Be Marucco | D29: GOL | F29: SIM | G29: Marucco / bernardom
A30: matheus | B30: Matheus | F30: SIM | G30: matheus
A31: merizi | B31: Merizi | D31: GOL | F31: SIM | G31: Merizi / Merizi GK / merizi
A32: miniderek | B32: Mini Derek | F32: SIM | G32: Mini Derek / Mini derek
A33: nathan | B33: Nathan | F33: SIM | G33: Nathan / nathan
A34: pairobson | B34: Mauro | C34: Mauro | G34: Pai Robson
A35: phelps | B35: Phelps | F35: SIM | G35: Felps / Phelps / phelps
A36: pietro | B36: Pietro | F36: SIM | G36: Pietro / pietro
A37: probst | B37: Probst | F37: SIM | G37: Probst / probst
A38: robson | B38: Robson | G38: Robson
A39: sograo | B39: Sograo | F39: SIM | G39: sograo
A40: vicente | B40: Vicente | F40: SIM | G40: vicente
A41: vitao | B41: Vitao | F41: SIM | G41: Vitao / vitao
...

Sheet TIMES
A1: As cores desenham o escudo e as faixas das artes. Evite verde: o Estúdio exporta WebM em fundo verde e o Chroma Key comeria a peça junto.
A3: id | B3: nome | C3: temporada | D3: sigla | E3: cor_1 | F3: cor_2 | G3: escudo_arquivo
A4: chelsea20 | B4: Chelsea | C4: 2020 | D4: CHE | E4: #1E4FD8 | F4: #FFFFFF
A5: psg20 | B5: PSG | C5: 2020 | D5: PSG | E5: #0B2265 | F5: #E30613 | G5: pegueisuagatalogo.png
A6: chelsea21 | B6: Chelsea | C6: 2021 | D6: CHE | E6: #1E4FD8 | F6: #FFFFFF
A7: psg21 | B7: PSG | C7: 2021 | D7: PSG | E7: #0B2265 | F7: #E30613 | G7: pegueisuagatalogo.png
A8: liverpool22 | B8: Liverpool | C8: 2022 | D8: LIV | E8: #C8102E | F8: #F2EFE5
A9: borussia22 | B9: Borussia | C9: 2022 | D9: BOR | E9: #F5D200 | F9: #141414
A10: boca23 | B10: Boca | C10: 2023 | D10: BOC | E10: #1B3A8C | F10: #F2C14E
A11: city23 | B11: City | C11: 2023 | D11: CIT | E11: #6CB4EE | F11: #0B2A4A
A12: branco24 | B12: Branco | C12: 2024 | D12: BRA | E12: #F2EFE5 | F12: #141414 | G12: dboafclogo.png
A13: preto24 | B13: Preto | C13: 2024 | D13: PRE | E13: #17181A | F13: #F2EFE5 | G13: criseumafclogo.png
A14: milanbe25 | B14: Milan Be | C14: 2025 | D14: MIL | E14: #C1121F | F14: #17181A
A15: jumentus25 | B15: Jumentus | C15: 2025 | D15: JUM | E15: #17181A | F15: #F2EFE5
A16: dentro26 | B16: Dentro FC | C16: 2026 | D16: DEN | E16: #F2B01E | F16: #17181A
A17: ferroviagra26 | B17: Ferroviagra | C17: 2026 | D17: FER | E17: #B01030 | F17: #F2B01E

Sheet JOGOS
A1: video_youtube = só o ID (o que vem depois de v= na URL). Empate: deixe campeao vazio.
A3: id | B3: temporada | C3: mes | D3: dia | E3: time_casa | F3: gols_casa | G3: gols_fora | H3: time_fora | I3: estadio | J3: campeao_time_id | K3: video_youtube
A4: 2020-12 | B4: 2020 | C4: Dezembro | E4: chelsea20 | F4: 6 | G4: 7 | H4: psg20 | I4: Elase
A5: 2021-07 | B5: 2021 | C5: Julho | E5: chelsea21 | F5: 10 | G5: 10 | H5: psg21 | I5: Elase
A6: 2021-12 | B6: 2021 | C6: Dezembro | E6: chelsea21 | F6: 6 | G6: 9 | H6: psg21 | I6: Paula Ramos
A7: 2022-04 | B7: 2022 | C7: Abril | E7: liverpool22 | F7: 4 | G7: 5 | H7: borussia22 | I7: Paula Ramos
A8: 2022-08 | B8: 2022 | C8: Agosto | E8: liverpool22 | F8: 1 | G8: 1 | H8: borussia22 | I8: Paula Ramos
A9: 2022-10 | B9: 2022 | C9: Outubro | E9: liverpool22 | F9: 10 | G9: 3 | H9: borussia22 | I9: Kretzer Indor
A10: 2023-06 | B10: 2023 | C10: Junho | E10: boca23 | F10: 0 | G10: 0 | H10: city23 | I10: Paula Ramos
A11: 2023-10 | B11: 2023 | C11: Outubro | E11: boca23 | F11: 3 | G11: 2 | H11: city23 | I11: Paula Ramos
A12: 2024-12 | B12: 2024 | C12: Dezembro | E12: branco24 | F12: 5 | G12: 3 | H12: preto24 | I12: Paula Ramos
A13: 2025-04 | B13: 2025 | C13: Abril | E13: milanbe25 | F13: 3 | G13: 0 | H13: jumentus25 | I13: Paula Ramos
A14: 2025-08 | B14: 2025 | C14: Agosto | E14: milanbe25 | F14: 3 | G14: 2 | H14: jumentus25 | I14: Paula Ramos
A15: 2026-04 | B15: 2026 | C15: Abril | E15: dentro26 | F15: 2 | G15: 3 | H15: ferroviagra26 | I15: Paula Ramos
A16: 2026-08 | B16: 2026 | C16: Agosto | E16: dentro26 | F16: 1 | G16: 1 | H16: ferroviagra26 | I16: Paula Ramos

Sheet VIDEOS
A1: Um vídeo por jogo. Cole só o ID do YouTube (o que vem depois de v= na URL). É daqui que a tela de Vídeos monta os cards. Os melhores momentos continuam na aba CLIPES.
A3: jogo_id | B3: video_youtube | C3: titulo | D3: duracao | E3: observacao
A4: 2020-12
A5: 2021-07
A6: 2021-12
A7: 2022-04
A8: 2022-08
A9: 2022-10
A10: 2023-06
A11: 2023-10
A12: 2024-12
A13: 2025-04
A14: 2025-08
A15: 2026-04
A16: 2026-08

Sheet ESCALACOES
A1: Puxada da aba Dados da planilha antiga. nota_1a5 vira o rostinho: 1 apagado ... 5 inspirado. gols_contra = gol contra (conta pro adversário, não entra no total do jogador). conta_no_placar = NAO quando o gol foi anulado/VAR: vale pro jogador mas não pro resultado.
A3: jogo_id | B3: jogador_id | C3: time_id | D3: gols | E3: assistencias | F3: campeao | G3: nota_1a5 | H3: numero | I3: gols_contra | J3: conta_no_placar
A4: 2020-12 | B4: letti | C4: chelsea20 | F4: NAO | J4: SIM
A5: 2020-12 | B5: pietro | C5: chelsea20 | F5: NAO | J5: SIM
A6: 2020-12 | B6: berna | C6: chelsea20 | F6: NAO | J6: SIM
A7: 2020-12 | B7: danilim | C7: chelsea20 | F7: NAO | J7: SIM
A8: 2020-12 | B8: phelps | C8: chelsea20 | F8: NAO | J8: SIM
A9: 2020-12 | B9: derek | C9: chelsea20 | F9: NAO | J9: SIM
A10: 2020-12 | B10: kretzer | C10: chelsea20 | F10: NAO | J10: SIM
A11: 2020-12 | B11: zaga | C11: chelsea20 | F11: NAO | J11: SIM
A12: 2020-12 | B12: garopaba | C12: psg20 | F12: SIM | J12: SIM
A13: 2020-12 | B13: nathan | C13: psg20 | F13: SIM | J13: SIM
A14: 2020-12 | B14: leo | C14: psg20 | F14: SIM | J14: SIM
A15: 2020-12 | B15: miniderek | C15: psg20 | F15: SIM | J15: SIM
... A51: 2021-12 | B51: vitao | C51: chelsea21 | F51: NAO | J51: SIM
A52: 2022-04 | B52: nathan | C52: borussia22 | D52: 1 | E52: 0 | F52: SIM | J52: SIM
A53: 2022-04 | B53: borba | C53: borussia22 | D53: 0 | E53: 0 | F53: SIM | J53: SIM
A54: 2022-04 | B54: danilim | C54: borussia22 | D54: 0 | E54: 0 | F54: SIM | J54: SIM
A55: 2022-04 | B55: pietro | C55: borussia22 | D55: 1 | E55: 1 | F55: SIM | J55: SIM
A56: 2022-04 | B56: zaga | C56: borussia22 | D56: 1 | E56: 1 | F56: SIM | J56: SIM
A57: 2022-04 | B57: andre | C57: borussia22 | D57: 0 | E57: 1 | F57: SIM | J57: SIM
A58: 2022-04 | B58: glauber | C58: borussia22 | D58: 2 | E58: 0 | F58: SIM | J58: SIM
A59: 2022-04 | B59: dereck | C59: borussia22 | D59: 0 | E59: 0 | F59: SIM | J59: SIM
A60: 2022-04 | B60: berna | C60: borussia22 | D60: 0 | E60: 0 | F60: SIM | J60: SIM
A61: 2022-04 | B61: marucco | C61: borussia22 | F61: SIM | J61: SIM
A62: 2022-04 | B62: kretzer | C62: liverpool22 | D62: 0 | E62: 0 | F62: NAO | J62: SIM
A63: 2022-04 | B63: fanta | C63: liverpool22 | D63: 0 | E63: 0 | F63: NAO | J63: SIM
A64: 2022-04 | B64: garopaba | C64: liverpool22 | D64: 0 | E64: 0 | F64: NAO | J64: SIM
A65: 2022-04 | B65: letti | C65: liverpool22 | D65: 1 | E65: 1 | F65: NAO | J65: SIM
A66: 2022-04 | B66: vitao | C66: liverpool22 | D66: 2 | E66: 2 | F66: NAO | J66: SIM
A67: 2022-04 | B67: leo | C67: liverpool22 | D67: 1 | E67: 0 | F67: NAO | J67: SIM
A68: 2022-04 | B68: derek | C68: liverpool22 | D68: 0 | E68: 0 | F68: NAO | J68: SIM
A69: 2022-04 | B69: phelps | C69: liverpool22 | D69: 0 | E69: 0 | F69: NAO | J69: SIM
A70: 2022-04 | B70: hanon | C70: liverpool22 | D70: 0 | E70: 0 | F70: NAO | J70: SIM
A71: 2022-04 | B71: correa | C71: liverpool22 | F71: NAO | J71: SIM
A72: 2022-08 | B72: nathan | C72: borussia22 | D72: 0 | E72: 0 | F72: NAO | J72: SIM
A73: 2022-08 | B73: borba | C73: borussia22 | D73: 0 | E73: 0 | F73: NAO | J73: SIM
A74: 2022-08 | B74: danilim | C74: borussia22 | D74: 0 | E74: 0 | F74: NAO | J74: SIM
A75: 2022-08 | B75: pietro | C75: borussia22 | D75: 0 | E75: 0 | F75: NAO | J75: SIM
A76: 2022-08 | B76: zaga | C76: borussia22 | D76: 0 | E76: 1 | F76: NAO | J76: SIM
...

Sheet DESEMPENHO
A1: Uma linha por jogador por time. Preencha nota_1a5 (1 apagado, 2 abaixo, 3 normal, 4 bom, 5 inspirado) — é o rostinho que aparece na página do time. As colunas cinzas são só referência, não mexa.
A3: time_id | B3: jogador_id | C3: apelido | D3: time_nome | E3: temporada | F3: nota_1a5 | G3: observacao
A4: chelsea20 | B4: danilim | C4: Danilim | D4: Chelsea | E4: 2020
A5: chelsea20 | B5: derek | C5: Derek | D5: Chelsea | E5: 2020
A6: chelsea20 | B6: letti | C6: Letti | D6: Chelsea | E6: 2020
A7: chelsea20 | B7: berna | C7: Mito | D7: Chelsea | E7: 2020
A8: chelsea20 | B8: phelps | C8: Phelps | D8: Chelsea | E8: 2020
A9: chelsea20 | B9: pietro | C9: Pietro | D9: Chelsea | E9: 2020
A10: chelsea20 | B10: kretzer | C10: Vitim | D10: Chelsea | E10: 2020
A11: chelsea20 | B11: zaga | C11: Zaga | D11: Chelsea | E11: 2020
A12: psg20 | B12: andre | C12: Andre | D12: PSG | E12: 2020
A13: psg20 | B13: borba | C13: Borba | D13: PSG | E13: 2020
A14: psg20 | B14: fanta | C14: Fanta | D14: PSG | E14: 2020
A15: psg20 | B15: garopaba | C15: Garopaba | D15: PSG | E15: 2020
... A158: ferroviagra26 | B158: zaga | C158: Zaga | D158: Ferroviagra | E158: 2026

Sheet TROFEUS
A1: Linhas EXEMPLO são ignoradas pelo site. trofeu_id válidos: campeao, artilheiro, garcom, craque, paredao, piroquinha
A3: temporada | B3: jogo_id | C3: trofeu_id | D3: jogador_id | E3: observacao
A4: 2025 | B4: EXEMPLO-1 | C4: artilheiro | D4: garopaba
A5: 2025 | B5: EXEMPLO-2 | C5: piroquinha | D5: fanta | E5: frango no primeiro tempo
A6: 2022 | B6: 2022-10 | C6: piroquinha | D6: fanta | E6: SIMULADO — apagar quando entrar o troféu de verdade
A7: 2023 | B7: 2023-10 | C7: artilheiro | D7: fanta | E7: SIMULADO — apagar quando entrar o troféu de verdade
A8: 2024 | B8: 2024-12 | C8: campeao | D8: fanta | E8: SIMULADO — apagar quando entrar o troféu de verdade
A9: 2025 | B9: 2025-08 | C9: craque | D9: fanta | E9: SIMULADO — apagar quando entrar o troféu de verdade
A10: 2026 | B10: 2026-04 | C10: garcom | D10: fanta | E10: SIMULADO — apagar quando entrar o troféu de verdade
A11: 2026 | B11: 2026-08 | C11: paredao | D11: fanta | E11: SIMULADO — apagar quando entrar o troféu de verdade

Sheet CLIPES
A1: Linhas EXEMPLO são ignoradas. Não corte vídeo: o site recorta pelo início e fim.
A3: jogador_id | B3: titulo | C3: video_youtube | D3: inicio_seg | E3: fim_seg | F3: temporada
A4: EXEMPLO | B4: Hat-trick na final | D4: 412 | E4: 438 | F4: 2024
A5: EXEMPLO | B5: Golaço de fora da área | D5: 95 | E5: 118 | F5: 2025

Sheet PENDENCIAS
A1: Prioridade 1 é o que mais atrapalha o site.
A3: prio | B3: tipo | C3: o que resolver | D3: quem | E3: resolvido em
A4: 2 | B4: gols | C4: 2020-12: a planilha antiga não guardou gols por jogador nesse jogo
A5: 2 | B5: gols | C5: 2021-07: a planilha antiga não guardou gols por jogador nesse jogo
A6: 2 | B6: gols | C6: 2021-12: a planilha antiga não guardou gols por jogador nesse jogo
A7: 2 | B7: gols | C7: 2024-12: gols lançados somam 7, placar é 5+3=8
A8: 2 | B8: gols | C8: 2026-08: gols lançados somam 3, placar é 1+1=2
A9: 3 | B9: lados | C9: 2022-08: placar empatado, não dá pra deduzir qual lado é liverpool22 e qual é borussia22 — confirme
A10: 3 | B10: lados | C10: 2023-06: placar empatado, não dá pra deduzir qual lado é boca23 e qual é city23 — confirme
A11: 4 | B11: nomes | C11: 'Berna' aparece nas escalações mas não está no RANKING Atual
A12: 4 | B12: nomes | C12: 'Bernardo C' aparece nas escalações mas não está no RANKING Atual
A13: 4 | B13: nomes | C13: 'Bernardo M' aparece nas escalações mas não está no RANKING Atual
A14: 4 | B14: nomes | C14: 'Dereck' aparece nas escalações mas não está no RANKING Atual
A15: 4 | B15: nomes | C15: 'Derek' aparece nas escalações mas não está no RANKING Atual
... A28: 4 | B28: nomes | C28: são a mesma pessoa? vitim, vitor — se sim, me diga o id que fica

Sheet LISTAS
A1: andre | B1: chelsea20 | C1: 2020-12 | D1: campeao
A2: arthur | B2: psg20 | C2: 2021-07 | D2: artilheiro
A3: bala | B3: chelsea21 | C3: 2021-12 | D3: garcom
A4: berna | B4: psg21 | C4: 2022-04 | D4: craque
A5: bernardoc | B5: liverpool22 | C5: 2022-08 | D5: paredao
A6: bernardom | B6: borussia22 | C6: 2022-10 | D6: piroquinha
A7: borba | B7: boca23 | C7: 2023-06
A8: bruno | B8: city23 | C8: 2023-10
A9: correa | B9: branco24 | C9: 2024-12
A10: danilim | B10: preto24 | C10: 2025-04
A11: davi | B11: milanbe25 | C11: 2025-08
A12: dereck | B12: jumentus25 | C12: 2026-04
A13: derek | B13: dentro26 | C13: 2026-08
A14: dereka | B14: ferroviagra26
A15: enzo
A16: fanta
A17: garopaba
A18: glauber
A19: gordo
A20: hanon
A21: henrique
A22: joao
A23: kretzer
A24: leo
A25: leobittencourt
A26: leogodinho
... A45: zaga

Sheet CONFERE
A1: Compara o placar de cada jogo com os gols lançados em ESCALACOES.
A3: jogo_id | B3: placar | C3: gols lançados | D3: escalados | E3: situação
A4: =JOGOS!A4 | B4: =JOGOS!F4+JOGOS!G4 | C4: =SUMIFS(ESCALACOES!$D:$D,ESCALACOES!$A:$A,$A4) | D4: =COUNTIFS(ESCALACOES!$A:$A,$A4) | E4: =IF(D4=0,"sem escalação",IF(B4=C4,"ok","faltam "&(B4-C4)&" gol(s)"))
A5: =JOGOS!A5 | B5: =JOGOS!F5+JOGOS!G5 | C5: =SUMIFS(ESCALACOES!$D:$D,ESCALACOES!$A:$A,$A5) | D5: =COUNTIFS(ESCALACOES!$A:$A,$A5) | E5: =IF(D5=0,"sem escalação",IF(B5=C5,"ok","faltam "&(B5-C5)&" gol(s)"))
A6: =JOGOS!A6 | B6: =JOGOS!F6+JOGOS!G6 | C6: =SUMIFS(ESCALACOES!$D:$D,ESCALACOES!$A:$A,$A6) | D6: =COUNTIFS(ESCALACOES!$A:$A,$A6) | E6: =IF(D6=0,"sem escalação",IF(B6=C6,"ok","faltam "&(B6-C6)&" gol(s)"))
A7: =JOGOS!A7 | B7: =JOGOS!F7+JOGOS!G7 | C7: =SUMIFS(ESCALACOES!$D:$D,ESCALACOES!$A:$A,$A7) | D7: =COUNTIFS(ESCALACOES!$A:$A,$A7) | E7: =IF(D7=0,"sem escalação",IF(B7=C7,"ok","faltam "&(B7-C7)&" gol(s)"))
A8: =JOGOS!A8 | B8: =JOGOS!F8+JOGOS!G8 | C8: =SUMIFS(ESCALACOES!$D:$D,ESCALACOES!$A:$A,$A8) | D8: =COUNTIFS(ESCALACOES!$A:$A,$A8) | E8: =IF(D8=0,"sem escalação",IF(B8=C8,"ok","faltam "&(B8-C8)&" gol(s)"))
A9: =JOGOS!A9 | B9: =JOGOS!F9+JOGOS!G9 | C9: =SUMIFS(ESCALACOES!$D:$D,ESCALACOES!$A:$A,$A9) | D9: =COUNTIFS(ESCALACOES!$A:$A,$A9) | E9: =IF(D9=0,"sem escalação",IF(B9=C9,"ok","faltam "&(B9-C9)&" gol(s)"))
A10: =JOGOS!A10 | B10: =JOGOS!F10+JOGOS!G10 | C10: =SUMIFS(ESCALACOES!$D:$D,ESCALACOES!$A:$A,$A10) | D10: =COUNTIFS(ESCALACOES!$A:$A,$A10) | E10: =IF(D10=0,"sem escalação",IF(B10=C10,"ok","faltam "&(B10-C10)&" gol(s)"))
A11: =JOGOS!A11 | B11: =JOGOS!F11+JOGOS!G11 | C11: =SUMIFS(ESCALACOES!$D:$D,ESCALACOES!$A:$A,$A11) | D11: =COUNTIFS(ESCALACOES!$A:$A,$A11) | E11: =IF(D11=0,"sem escalação",IF(B11=C11,"ok","faltam "&(B11-C11)&" gol(s)"))
A12: =JOGOS!A12 | B12: =JOGOS!F12+JOGOS!G12 | C12: =SUMIFS(ESCALACOES!$D:$D,ESCALACOES!$A:$A,$A12) | D12: =COUNTIFS(ESCALACOES!$A:$A,$A12) | E12: =IF(D12=0,"sem escalação",IF(B12=C12,"ok","faltam "&(B12-C12)&" gol(s)"))
A13: =JOGOS!A13 | B13: =JOGOS!F13+JOGOS!G13 | C13: =SUMIFS(ESCALACOES!$D:$D,ESCALACOES!$A:$A,$A13) | D13: =COUNTIFS(ESCALACOES!$A:$A,$A13) | E13: =IF(D13=0,"sem escalação",IF(B13=C13,"ok","faltam "&(B13-C13)&" gol(s)"))
A14: =JOGOS!A14 | B14: =JOGOS!F14+JOGOS!G14 | C14: =SUMIFS(ESCALACOES!$D:$D,ESCALACOES!$A:$A,$A14) | D14: =COUNTIFS(ESCALACOES!$A:$A,$A14) | E14: =IF(D14=0,"sem escalação",IF(B14=C14,"ok","faltam "&(B14-C14)&" gol(s)"))
A15: =JOGOS!A15 | B15: =JOGOS!F15+JOGOS!G15 | C15: =SUMIFS(ESCALACOES!$D:$D,ESCALACOES!$A:$A,$A15) | D15: =COUNTIFS(ESCALACOES!$A:$A,$A15) | E15: =IF(D15=0,"sem escalação",IF(B15=C15,"ok","faltam "&(B15-C15)&" gol(s)"))
A16: =JOGOS!A16 | B16: =JOGOS!F16+JOGOS!G16 | C16: =SUMIFS(ESCALACOES!$D:$D,ESCALACOES!$A:$A,$A16) | D16: =COUNTIFS(ESCALACOES!$A:$A,$A16) | E16: =IF(D16=0,"sem escalação",IF(B16=C16,"ok","faltam "&(B16-C16)&" gol(s)"))

Sheet LANCES 2026-04
A1: Lances marcados deste jogo. O app grava e lê daqui. A chave abaixo é o que libera a edição no app — trate como senha do grupo.
A2: chave_de_acesso | B2: TROQUE-ESTA-CHAVE | C2: <- digite a sua aqui, depois de subir pro Drive | D2: dentro26 x ferroviagra26
A4: min | B4: time | C4: tipo | D4: jogador | E4: xg | F4: por | G4: em

Sheet LANCES 2026-08
A1: Lances marcados deste jogo. O app grava e lê daqui. A chave abaixo é o que libera a edição no app — trate como senha do grupo.
A2: chave_de_acesso | B2: TROQUE-ESTA-CHAVE | C2: <- digite a sua aqui, depois de subir pro Drive | D2: dentro26 x ferroviagra26
A4: min | B4: time | C4: tipo | D4: jogador | E4: xg | F4: por | G4: em
